Workbook

Sheet Version
A4: Vivante DC9X00L series - Product Order Form
A6: Version | B6: Description | C6: Date

Sheet UserGuide
A1: This is a guide for how to use the POF file
A3: "Version" sheet: the page to track the POF file version
A6: "UserGuide" sheet: This page gives the user guide to use the POF file
A8: "General" sheet: Some basic general information of the project
A11: "Configuration" sheet: Hardware configuration options
A14: "ProductFeatureList" sheet: This is a read-only sheet to show the complete feature list, including configurable and not configurable ones Notice that ,this sheet is the final result of this IP
A16: "CR" sheet: This sheet is used for recording customer request on IP product customization change

Sheet General
A1: Please fill necessary project information below, for general reference purpose
A3: General Information | B3: Customer's Answer | C3: Answer Example
A4: Company name | C4: ABC Corp.
A5: Project name or identifier | C5: Aspen201
A6: Target process (e.g. TSMC N7) | C6: TSMC N7
A7: Target RTL freeze date | C7: Mid December, 2024
A8: Target tape out date | C8: End August, 2025
A9: Host OS (e.g. Linux 3.10) | C9: Linux 6.6

Sheet Configuration
A1: Product Order Form for DCNanoUltra-XR Display Controller IP
A2: Category | B2: DCNanoUltra-XR Series Product Features | D2: Customer Config | E2: Impact by Feature | F2: Customer Comments | G2: VSI Comments
A3: Pixel Throughput | B3: Pixel per Cycle | D3: 1 | E3: =IF(D3=1,"4K60 FPS Core clock 600MHz Pixel clock 150MHz(when 4ppc port)","4K120 FPS Core clock 600MHz Pixel clock 300MHz(when 4ppc port)") -> 4K60 FPS Core clock 600MHz Pixel clock 150MHz(when 4ppc port)
A4: Pixel Pre-processing | B4: Video Layers | D4: 2 | G4: Layer number configrable; Default 1; YUV+RGB format; Tile/Rotation/FlipX,Y/Scaler;
B5: Graphic Layers | D5: 0 | G5: Layer number configrable; Default 0; RGB format only ; Tile/no Rotation/FlipX,Y/Scaler;
B6: Simple Layers | D6: 2 | G6: Layer number configrable; Default 1; Linear YUV+RGB format; Flip X,Y; No Tile/No Rotation/No Scaler in default config; No Decompression
B7: Cursor Layers | D7: 2 | G7: Max size 256x256, ARGB8 Linear
A8: Pixel Post-processing | B8: Max Output devices support | D8: 2
A9: DeCompression | B9: Input frame buffer decompression | D9: DECNano3.0
B10: AXI interface | D10: 256bits
A12: Per-Layer Type Configuration (configure each layer independently)
A13: Category | B13: Layer ID | C13: Configure Feature | D13: Customer Config | E13: Impact by Feature | F13: Customer Comments | G13: VSI Comments
A14: Pixel Pre-processing | B14: Layer0 | C14: Layer Type | D14: =IF(0<$D$4,"Video",IF(0<$D$4+$D$5,"Graphic",IF(0<$D$4+$D$5+$D$6,"Simple","Not Used"))) -> Video
C15: Compression | D15: Support | E15: =IF(D15="Not Support","","357.3K gates + 5.25KB RAM") -> 357.3K gates + 5.25KB RAM
C16: HDR | D16: Not Support | E16: =IF(D16="Not Support","",IF($D$3=2,"567.7K gates","361.9K gates"))
C17: Scaler | D17: Not Support | E17: =IF(D17="Not Support","",IF($D$3=2,"348.1K gates + 120KB RAM","207.9K gates + 96.56KB RAM")) | G17: Scaler 8x~1/4x
B18: Layer1 | C18: Layer Type | D18: =IF(1<$D$4,"Video",IF(1<$D$4+$D$5,"Graphic",IF(1<$D$4+$D$5+$D$6,"Simple","Not Used"))) -> Video
C19: Compression | D19: Support | E19: =IF(D19="Not Support","","357.3K gates + 5.25KB RAM") -> 357.3K gates + 5.25KB RAM
C20: HDR | D20: Not Support | E20: =IF(D20="Not Support","",IF($D$3=2,"567.7K gates","361.9K gates"))
C21: Scaler | D21: Not Support | E21: =IF(D21="Not Support","",IF($D$3=2,"348.1K gates + 120KB RAM","207.9K gates + 96.56KB RAM")) | G21: Scaler 8x~1/4x
B22: Layer2 | C22: Layer Type | D22: =IF(2<$D$4,"Video",IF(2<$D$4+$D$5,"Graphic",IF(2<$D$4+$D$5+$D$6,"Simple","Not Used"))) -> Simple
C23: Compression | D23: Not Support | E23: =IF(D23="Not Support","","357.3K gates + 5.25KB RAM")
C24: HDR | D24: Not Support | E24: =IF(D24="Not Support","",IF($D$3=2,"567.7K gates","361.9K gates"))
C25: Scaler | D25: Not Support | E25: =IF(D25="Not Support","",IF($D$3=2,"348.1K gates + 120KB RAM","207.9K gates + 96.56KB RAM")) | G25: Scaler 8x~1/4x
B26: Layer3 | C26: Layer Type | D26: =IF(3<$D$4,"Video",IF(3<$D$4+$D$5,"Graphic",IF(3<$D$4+$D$5+$D$6,"Simple","Not Used"))) -> Simple
C27: Compression | D27: Not Support | E27: =IF(D27="Not Support","","357.3K gates + 5.25KB RAM")
C28: HDR | D28: Not Support | E28: =IF(D28="Not Support","",IF($D$3=2,"567.7K gates","361.9K gates"))
C29: Scaler | D29: Not Support | E29: =IF(D29="Not Support","",IF($D$3=2,"348.1K gates + 120KB RAM","207.9K gates + 96.56KB RAM")) | G29: Scaler 8x~1/4x
B30: Layer4 | C30: Layer Type | D30: =IF(4<$D$4,"Video",IF(4<$D$4+$D$5,"Graphic",IF(4<$D$4+$D$5+$D$6,"Simple","Not Used"))) -> Not Used
C31: Compression | D31: Not Support | E31: =IF(D31="Not Support","","357.3K gates + 5.25KB RAM")
C32: HDR | D32: Not Support | E32: =IF(D32="Not Support","",IF($D$3=2,"567.7K gates","361.9K gates"))
C33: Scaler | D33: Not Support | E33: =IF(D33="Not Support","",IF($D$3=2,"348.1K gates + 120KB RAM","207.9K gates + 96.56KB RAM")) | G33: Scaler 8x~1/4x
B34: Layer5 | C34: Layer Type | D34: =IF(5<$D$4,"Video",IF(5<$D$4+$D$5,"Graphic",IF(5<$D$4+$D$5+$D$6,"Simple","Not Used"))) -> Not Used
C35: Compression | D35: Not Support | E35: =IF(D35="Not Support","","357.3K gates + 5.25KB RAM")
C36: HDR | D36: Not Support | E36: =IF(D36="Not Support","",IF($D$3=2,"567.7K gates","361.9K gates"))
C37: Scaler | D37: Not Support | E37: =IF(D37="Not Support","",IF($D$3=2,"348.1K gates + 120KB RAM","207.9K gates + 96.56KB RAM")) | G37: Scaler 8x~1/4x
B38: Layer6 | C38: Layer Type | D38: =IF(6<$D$4,"Video",IF(6<$D$4+$D$5,"Graphic",IF(6<$D$4+$D$5+$D$6,"Simple","Not Used"))) -> Not Used
C39: Compression | D39: Not Support | E39: =IF(D39="Not Support","","357.3K gates + 5.25KB RAM")
C40: HDR | D40: Not Support | E40: =IF(D40="Not Support","",IF($D$3=2,"567.7K gates","361.9K gates"))
C41: Scaler | D41: Not Support | E41: =IF(D41="Not Support","",IF($D$3=2,"348.1K gates + 120KB RAM","207.9K gates + 96.56KB RAM")) | G41: Scaler 8x~1/4x
...

Sheet ProductFeatureList
A1: Category | C1: DCNanoUltra-XR Product Features | E1: VSI Comment
A2: IP Version | D2: DCNanoUltra-XR
A3: Display Throughput (Resolution@Frame Rate) | C3: Max Display Resolution for Single Display | D3: =IF(Configuration!D3=1,"4096x2160@60fps","4096x2160@120fps") -> 4096x2160@60fps
C4: Max Display Resolution for Multiple Display | D4: =IF(Configuration!D3=1,IF(D7>1,"4096x2160@120fps","Not Support"),IF(D7=1,"Not Support","7680x4320@60fps")) -> 4096x2160@120fps | E4: Multi-Display splice mode
A5: Pixel Thoughput | C5: Pixel Rate (Pixels per Cycle) | D5: =Configuration!D3 -> 1
A6: HW Resource | C6: Pixel Pre-processing | D6: =ROUNDUP(SUM(Configuration!D4:D7)/8,0) -> 1
C7: Pixel Post-processing | D7: =Configuration!D8 -> 2
A8: Decompression | C8: Input frame buffer decompression | D8: =Configuration!D9 -> DECNano3.0
A9: Data BUS | C9: AXI4.0 address width | D9: 48bit | E9: For Pixel Pre-processing
C10: AXI4.0 read interface | D10: =IF(SUM(Configuration!D4:D7)=0,"Not Support",(D6*IF(ROUNDUP(SUM(Configuration!D4:D7)/D6,0)>3,2,1))&"x"&Configuration!D10) -> 2x256bits
C11: AXI4.0 write interface | D11: =IF(Configuration!D101="Not Used","Not Support","1x"&Configuration!D10) -> 1x256bits | E11: For Write Back
A12: Config BUS | C12: APB3.0 interface | D12: =D6+1&"x32bits" -> 2x32bits
A13: Pixel Pre-processing | B13: Cursor Layer | D13: =Configuration!D7 -> 2
B14: Layer0 | C14: Layer type | D14: =Configuration!D14 -> Video
C15: Format | D15: =IF(Configuration!D14="Not Used","",IF(Configuration!D14="Video","YUV+RGB format;",IF(Configuration!D14="Graphic","RGB format only;",IF(Configuration!D14="Simple","Linear YUV+RGB format;","ARGB8")))) -> YUV+RGB format;
C16: Tilemode | D16: =IF(Configuration!D14="Not Used","",IF(OR(Configuration!D14="Simple",Configuration!D14="Cursor"),"Linear","Tile&Linear")) -> Tile&Linear
C17: Decompression | D17: =Configuration!D15 -> Support
C18: Max resolution | D18: =IF(Configuration!D14="Not Used","",IF(Configuration!D14="Cursor","256x256","4096x2160")) -> 4096x2160
C19: Rotation with tile input formats | D19: =IF(Configuration!D14="Not Used","",IF(OR(Configuration!D14="Video"),"Support","Not Support")) -> Support | E19: Rotation 90°/270°
C20: Flip | D20: =IF(Configuration!D14="Not Used","",IF(Configuration!D14="Cursor","Not Support","Support")) -> Support | E20: Flip Y/Flip X/Flip X&Flip Y
C21: Color Key | D21: =IF(Configuration!D14="Not Used","","Support") -> Support
C22: Crop | D22: =IF(Configuration!D14="Not Used","","Support") -> Support
C23: Swizzle | D23: =IF(Configuration!D14="Not Used","","Support") -> Support
C24: Scaler | D24: =Configuration!D17 -> Not Support | E24: Range 1/4x~8x, Kernel 8x4
C25: HDR | D25: =Configuration!D16 -> Not Support
C26: YUV2RGB | D26: =IF(Configuration!D14="Not Used","",IF(OR(Configuration!D14="Video",Configuration!D14="Simple"),"Support","Not Support")) -> Support
C27: Solid color | D27: =IF(Configuration!D14="Not Used","","Support") -> Support
B28: Layer1 | C28: Layer type | D28: =Configuration!D18 -> Video
C29: Format | D29: =IF(Configuration!D18="Not Used","",IF(Configuration!D18="Video","YUV+RGB format;",IF(Configuration!D18="Graphic","RGB format only;",IF(Configuration!D18="Simple","Linear YUV+RGB format;","ARGB8")))) -> YUV+RGB format;
C30: Tilemode | D30: =IF(Configuration!D18="Not Used","",IF(OR(Configuration!D18="Simple",Configuration!D18="Cursor"),"Linear","Tile&Linear")) -> Tile&Linear
C31: Decompression | D31: =Configuration!D19 -> Support
C32: Max resolution | D32: =IF(Configuration!D18="Not Used","",IF(Configuration!D18="Cursor","256x256","4096x2160")) -> 4096x2160
C33: Rotation with tile input formats | D33: =IF(Configuration!D18="Not Used","",IF(OR(Configuration!D18="Video"),"Support","Not Support")) -> Support | E33: Rotation 90°/270°
C34: Flip | D34: =IF(Configuration!D18="Not Used","",IF(Configuration!D18="Cursor","Not Support","Support")) -> Support | E34: Flip Y/Flip X/Flip X&Flip Y
C35: Color Key | D35: =IF(Configuration!D18="Not Used","","Support") -> Support
C36: Crop | D36: =IF(Configuration!D18="Not Used","","Support") -> Support
C37: Swizzle | D37: =IF(Configuration!D18="Not Used","","Support") -> Support
C38: Scaler | D38: =Configuration!D21 -> Not Support | E38: Range 1/4x~8x, Kernel 8x4
C39: HDR | D39: =Configuration!D20 -> Not Support
C40: YUV2RGB | D40: =IF(Configuration!D18="Not Used","",IF(OR(Configuration!D18="Video",Configuration!D18="Simple"),"Support","Not Support")) -> Support
...

Sheet CR
A2: Feature | B2: Requests Descriptions | C2: Customer Comment | D2: VSI Comment
A3: 4ROI DMA | B3: CR项；need support 4 ROI DMA | D3: CR
A4: Sync mode with offset | B4: CR项；带offset syncmode | D4: CR
A5: EVS mode with offset | B5: CR项；带offset EVS | D5: CR
A6: 行中断周期intr | B6: CR项；16行为粒度，最大1024行, 自动发起行intr | D6: CR
A7: New format for simple layer | B7: CR项；增加 YUV422 1 Planar interleave 10bit | D7: CR
A10: YUV422 1 Planar interleave 8/10bit

Sheet Schedule
A1: Owner | B1: Latest update | D1: T0
B2: 46252 | D2: 46265
A3: Milestone | B3: Release Date | C3: weeks | D3: Description | E3: If T0 20260831 ,试算
A4: RTL V0.5 | B4: T0+4 | C4: 4 | D4: * Ready feature in. * Synthesis and Physical Design trial run * without new feature Flexa/mulit ROI ,offset | E4: =$D$2+C4*7 -> 46293
A5: RTL V0.7 | B5: T0+13 | C5: 13 | D5: * ALL feature in * 80% regression clean * Lint clean, CDC clean * 90% area accuracy * IO and memory freeze | E5: =$D$2+C5*7 -> 46356
A6: SW V0.7 | B6: T0+15 | C6: 15 | D6: * SW Bring up version | E6: =$D$2+C6*7 -> 46370
A7: RTL/SW V1.0 | B7: T0+20 | C7: 20 | D7: RTL/SW Final： * 100% Regression clean * FPGA Clean * RTL Frozen * Fully verified | E7: =$D$2+C7*7 -> 46405

Sheet Discussion record
A1: 1. 4X ROI cursor layer
A16: 特征和约束
A17: 1. A/B/C/D 4个ROI 形状互不对称，一定紧贴屏幕边缘
A18: 2. 其中A/D 最高128p, 宽可配
A19: 3. 其中B/C 最宽128p, 高可配
A20: *不排斥从DDR读数据，但需要尽量不读无效数据(图中淡黄色框部分)
A22: Alpha Mask Bandwidth per panel（A8）
A23: Display Resolution Width | B23: Display Resolution Hight | C23: FPS | D23: A8/I8 BW（MB/S） | E23: Peak BW (MB/S)
A24: 3840 | B24: 2400 | C24: 81 | D24: =(40*(B24-40-40)+40*A24)*1*C24/1024/1024*2 -> 38.067627 | E24: =A24*B24*C24*(2)/1024/1024/2 -> 711.91406
A25: 2880 | B25: 1800 | C25: 144 | D25: =(40*(B25-40-40)+40*A25)*1*C25/1024/1024*2 -> 50.537109 | E25: =A25*B25*C25*(2)/1024/1024/2 -> 711.91406
A26: *a 这里的峰值带宽理论上不是出现在A/B/C/D的遮挡层（因为UI界面和遮挡层不应该重叠），而是出现在GPU 的UI 层（图中橘色部分）。此时场景是主视频层（From SRE）ARGB flexa without bw cost + GPU 压缩后的ARGB 2BPP （2：1压缩）
A27: *b 如果a推论不成立（即UI界面和遮挡层存在重叠，峰值带宽各自加上A8/I8 BW即可）
A28: 2. DPU Start with EVS mode
A29: 特征和约束 | B29: 此时屏幕
A30: start flow
A31: * DPU 上电后，panel start free run mode(正常显示) | B31: Video Mode 常规background/logo only . with offset !!(DPU 内部实现，DP sync offset cnt 为正)，只能工作在DP sync
A32: * 软件控制 DPU panel stop ， | B32: 屏幕黑屏，显示停止
A33: * 软件寄存器配置 | B33: 屏幕黑屏，显示停止
A34: * DPU EVS mode start | B34: EVS Mode 刷新屏幕，DPU stand by. with offset !!
A36: End flow
A37: * EVS mode stop | B37: TODO: check clock of EVS trigger
B38: offset 粒度是pixel cycle , 按最大1帧.32bit cnt
A40: 3. 一路输出复制另外一路输出
A41: 场景 | B41: 带宽
A42: copy mode without offset | B42: 1x display 内容
A43: copy mode with offset | B43: 2x display 内容
A44: 结论：offset 模式（EVS）下，copy mode 不开
A47: Feature | B47: Requests Descriptions | C47: Customer Comment | D47: VSI Comment
A48: 最大分吞吐量 | B48: 2880×1800 @ 120 fps (每个引擎) | C48: 调整到144FPS
A49: 最大分辨率 | B49: 3840X2400 | C49: 调整到81FPS | D49: 72 FPS
A50: PPC | B50: 1xPPC | D50: 1PPC
A51: core clock | B51: 800Mhz | C51: 调整到900MHz
A52: 实例数 (panel number) | B52: 2 个 (每个 OLED 对应 1 个)
A53: 输入色彩格式 | B53: 主视频: RGB888, RGB101010 | D53: 没有tile; with flexa 20260825:YUV DP_ISP/VPU without flexa YUV422 1 Planar interleave 8bit/10bit CR项；增加 YUV422 1 Planar interleave 10bit
B54: 叠加层: ARGB8888 | D54: GC, with DECNano 3.0
B55: Cursor: ARGB8888 | D55: CR项；need support roi >= 4 . 软件OK
A56: 输出色彩格式 | B56: RGB, YUV444, YUV422 | D56: 10bit刚需, 8bit也需要
A57: CSC 色彩空间转换 | B57: 支持输入 / 输出格式之间全部转换
A58: 非线性 | B58: 支持非线性输入
A59: 图层合成 | B59: 2x3 层: 1 主视频层 + 1 叠加层 + 1 光标层 (1xsimple layer+1OSD(DCnaond) + 1 cursor layer) 图像合成在非线性空间, GPU 输出OSD 在线性空间, 叠加层osd blending 前需要加gamma | D59: Offset相位需要错开10行, 最大场景±半帧
...

Sheet Format
A1: RDMA format | H1: Write back format
A2: Color Format | B2: Plane | C2: Tile Mode | D2: Video layer (Rotation90/270) | E2: Simple layer | F2: Video layer | H2: Color Format | I2: Plane | J2: Tile Mode
A3: A2RGB10 | B3: 1 | C3: Linear | D3: Not support | E3: Support | F3: Support | H3: ARGB8888 | I3: 1 | J3: Linear
C4: Tile 4x4 | D4: Support | E4: Not support | F4: Support | H4: ARGB8565
A5: X2RGB10 | B5: 1 | C5: Linear | D5: Not support | E5: Support | F5: Support | H5: ARGB4444
C6: Tile 4x4 | D6: Support | E6: Not support | F6: Support | H6: ARGB1555
A7: ARGB8888 | B7: 1 | C7: Linear | D7: Not support | E7: Support | F7: Support | H7: XRGB888
C8: Tile 4x4 | D8: Support | E8: Not support | F8: Support | H8: RGB888
A9: ARGB8565 | B9: 1 | C9: Linear | D9: Not support | E9: Support | F9: Support | H9: RGB565
C10: Tile 4x4 | D10: Support | E10: Not support | F10: Support | H10: YUY2(YUV422)
A11: ARGB4444 | B11: 1 | C11: Linear | D11: Not support | E11: Support | F11: Support | H11: Gray(L8)
C12: Tile 4x4 | D12: Support | E12: Not support | F12: Support | H12: X2RGB10
A13: ARGB1555 | B13: 1 | C13: Linear | D13: Not support | E13: Support | F13: Support | H13: P010(YUV420) | I13: 2
C14: Tile 4x4 | D14: Support | E14: Not support | F14: Support | H14: NV16(YUV422)
A15: RGB888 | B15: 1 | C15: Linear | D15: Not support | E15: Support | F15: Support | H15: P210(YUV422)
B16: 1 | C16: Tile 4x4 | D16: Support | E16: Not support | F16: Support | H16: NV12(YUV420)
A17: RGB565 | B17: 1 | C17: Linear | D17: Not support | E17: Support | F17: Support
C18: Tile 4x4 | D18: Support | E18: Not support | F18: Support | H18: Outif format
H19: Port | I19: Color Format | J19: Bitdepth
A20: P210(YUV422) | B20: 2 | C20: Tile 8x8 | D20: Support | E20: Not support | F20: Support | H20: DSI | I20: YUV422 | J20: 8
A21: YUY2(YUV422) 8bit packed | B21: 1 | C21: Tile 4x4 | D21: Support | E21: Not support | F21: Support | J21: 10
B22: 1 | C22: Linear | D22: Not support | E22: Support | F22: Support | I22: RGB888 | J22: 8
A23: Gray(L8) | B23: 1 | C23: Linear | D23: Not support | E23: Support | F23: Support | I23: RGB10 | J23: 10
B24: 1 | C24: Tile 4x4 | D24: Support | E24: Not support | F24: Support | H24: DP | I24: YUV444 | J24: 8
A25: NV12(YUV420) | B25: 2 | C25: Linear | D25: Not support | E25: Not support | F25: Support | J25: 10
A26: L8A8 | B26: 1 | C26: Linear | D26: Not support | E26: Support | F26: Support | I26: YUV422 | J26: 8
B27: 1 | C27: Tile 4x4 | D27: Support | E27: Not support | F27: Support | J27: 10
A28: A8 | B28: 1 | C28: Linear | D28: Not support | E28: Support | F28: Support | I28: RGB888 | J28: 8
I29: RGB10 | J29: 10
A31: Support | B31: with flexa
