Workbook

Sheet Version
A4: Vivante DC9X00L series - Product Order Form
A6: Version | B6: Description | C6: Date

Sheet UserGuide
A1: This is a guide for how to use the POF file
A3: "Version" sheet: the page to track the POF file version
A6: "UserGuide" sheet: This page gives the user guide to use the POF file
A8: "General" sheet: Some basic general information of the project
A11: "Configuration" sheet: Hardware configuration options
A14: "ProductFeatureList" sheet: This is a read-only sheet to show the complete feature list, including configurable and not configurable ones Notice that ,this sheet is the final result of this IP
A16: "CR" sheet: This sheet is used for recording customer request on IP product customization change

Sheet General
A1: Please fill necessary project information below, for general reference purpose
A3: General Information | B3: Customer's Answer | C3: Answer Example
A4: Company name | C4: ABC Corp.
A5: Project name or identifier | C5: Aspen201
A6: Target process (e.g. TSMC N7) | C6: TSMC N7
A7: Target RTL freeze date | C7: Mid December, 2024
A8: Target tape out date | C8: End August, 2025
A9: Host OS (e.g. Linux 3.10) | C9: Linux 6.6

Sheet Configuration
A1: Product Order Form for DC9X00 Series Display Controller IP
A2: Category | B2: DC9X00/DC9X00L Series Product Features | D2: Customer Config | E2: Impact by Feature | F2: Customer Comments | G2: VSI Comments
A3: Pixel Throughput | B3: Pixel per Cycle | D3: 2 | E3: =IF(D3=1,"4K60 FPS Core clock 600MHz Pixel clock 150MHz(when 4ppc port)","4K120 FPS Core clock 600MHz Pixel clock 300MHz(when 4ppc port)") -> 4K120 FPS Core clock 600MHz Pixel clock 300MHz(when 4ppc port) | F3: 单条流水线性能，可满足4K120fps | G3: 1ppc DC9x00L 2ppc DC9x00 | K3: 4K120FPS Core clock 1.2G without splice mode Core clock 600MHz with splice mode Pixel clock 300MHz(4ppc port)
A4: Pixel Pre-processing | B4: Video Layers | D4: 4 | F4: 比graphic layer多出YUV格式，最完善的layer。 | G4: Layer number configrable; Default 1; YUV+RGB format; Tile/Rotation/FlipX,Y/Scaler; Fetch up to 4 images from memory by one layer without overlap in vertical (SuperDMA1.0)
B5: Graphic Layers | D5: 4 | F5: 普通layer。Graphic layer 和 video layer 分别选用 4 个。如面积超出，可进行删减。 | G5: Layer number configrable; Default 0; RGB format only ; Tile/No Rotation/FlipX,Y/Scaler; Fetch up to 4 images from memory by one layer without overlap in vertical (SuperDMA1.0)
B6: Simple Layers | D6: 0 | F6: 不选用。 | G6: Layer number configrable; Default 1; Linear YUV+RGB format; Flip X,Y; No Tile/No Rotation/No Scaler in default config; Fetch up to 4 images from memory by one layer without overlap in vertical (SuperDMA1.0) No Decompression
B7: Cursor Layers | D7: 4 | F7: 对应4个屏幕 | G7: Max size 256x256, ARGB8 Linear
A8: Pixel Post-processing | B8: Max Output devices support | D8: 4 | F8: 输出4个屏幕
A9: DeCompression | B9: Input frame buffer decompression | D9: DEC400 | F9: 选用。
B10: AXI interface | D10: 256bits
A12: Per-Layer Type Configuration (configure each layer independently)
A13: Category | B13: Layer ID | C13: Configure | E13: Impact by Feature | F13: Customer Comments | G13: VSI Comments
A14: Pixel Pre-processing | B14: Layer0 | C14: Layer Type | D14: =IF(0<$D$4,"Video",IF(0<$D$4+$D$5,"Graphic",IF(0<$D$4+$D$5+$D$6,"Simple","Not Used"))) -> Video
C15: Compression | D15: Support | E15: =IF(D15="Not Support","","357.3K gates + 5.25KB RAM") -> 357.3K gates + 5.25KB RAM
C16: HDR | D16: Support | E16: =IF(D16="Not Support","",IF($D$3=2,"567.7K gates","361.9K gates")) -> 567.7K gates
C17: Scaler | D17: Support | E17: =IF(D17="Not Support","",IF($D$3=2,"348.1K gates + 120KB RAM","207.9K gates + 96.56KB RAM")) -> 348.1K gates + 120KB RAM
B18: Layer1 | C18: Layer Type | D18: =IF(1<$D$4,"Video",IF(1<$D$4+$D$5,"Graphic",IF(1<$D$4+$D$5+$D$6,"Simple","Not Used"))) -> Video
C19: Compression | D19: Support | E19: =IF(D19="Not Support","","357.3K gates + 5.25KB RAM") -> 357.3K gates + 5.25KB RAM
C20: HDR | D20: Support | E20: =IF(D20="Not Support","",IF($D$3=2,"567.7K gates","361.9K gates")) -> 567.7K gates
C21: Scaler | D21: Support | E21: =IF(D21="Not Support","",IF($D$3=2,"348.1K gates + 120KB RAM","207.9K gates + 96.56KB RAM")) -> 348.1K gates + 120KB RAM
B22: Layer2 | C22: Layer Type | D22: =IF(2<$D$4,"Video",IF(2<$D$4+$D$5,"Graphic",IF(2<$D$4+$D$5+$D$6,"Simple","Not Used"))) -> Video
C23: Compression | D23: Support | E23: =IF(D23="Not Support","","357.3K gates + 5.25KB RAM") -> 357.3K gates + 5.25KB RAM
C24: HDR | D24: Support | E24: =IF(D24="Not Support","",IF($D$3=2,"567.7K gates","361.9K gates")) -> 567.7K gates
C25: Scaler | D25: Support | E25: =IF(D25="Not Support","",IF($D$3=2,"348.1K gates + 120KB RAM","207.9K gates + 96.56KB RAM")) -> 348.1K gates + 120KB RAM
B26: Layer3 | C26: Layer Type | D26: =IF(3<$D$4,"Video",IF(3<$D$4+$D$5,"Graphic",IF(3<$D$4+$D$5+$D$6,"Simple","Not Used"))) -> Video
C27: Compression | D27: Support | E27: =IF(D27="Not Support","","357.3K gates + 5.25KB RAM") -> 357.3K gates + 5.25KB RAM
C28: HDR | D28: Support | E28: =IF(D28="Not Support","",IF($D$3=2,"567.7K gates","361.9K gates")) -> 567.7K gates
C29: Scaler | D29: Support | E29: =IF(D29="Not Support","",IF($D$3=2,"348.1K gates + 120KB RAM","207.9K gates + 96.56KB RAM")) -> 348.1K gates + 120KB RAM
B30: Layer4 | C30: Layer Type | D30: =IF(4<$D$4,"Video",IF(4<$D$4+$D$5,"Graphic",IF(4<$D$4+$D$5+$D$6,"Simple","Not Used"))) -> Graphic
C31: Compression | D31: Support | E31: =IF(D31="Not Support","","357.3K gates + 5.25KB RAM") -> 357.3K gates + 5.25KB RAM
C32: HDR | D32: Support | E32: =IF(D32="Not Support","",IF($D$3=2,"567.7K gates","361.9K gates")) -> 567.7K gates
C33: Scaler | D33: Not Support | E33: =IF(D33="Not Support","",IF($D$3=2,"348.1K gates + 120KB RAM","207.9K gates + 96.56KB RAM"))
B34: Layer5 | C34: Layer Type | D34: =IF(5<$D$4,"Video",IF(5<$D$4+$D$5,"Graphic",IF(5<$D$4+$D$5+$D$6,"Simple","Not Used"))) -> Graphic
C35: Compression | D35: Support | E35: =IF(D35="Not Support","","357.3K gates + 5.25KB RAM") -> 357.3K gates + 5.25KB RAM
C36: HDR | D36: Support | E36: =IF(D36="Not Support","",IF($D$3=2,"567.7K gates","361.9K gates")) -> 567.7K gates
C37: Scaler | D37: Not Support | E37: =IF(D37="Not Support","",IF($D$3=2,"348.1K gates + 120KB RAM","207.9K gates + 96.56KB RAM"))
B38: Layer6 | C38: Layer Type | D38: =IF(6<$D$4,"Video",IF(6<$D$4+$D$5,"Graphic",IF(6<$D$4+$D$5+$D$6,"Simple","Not Used"))) -> Graphic
C39: Compression | D39: Support | E39: =IF(D39="Not Support","","357.3K gates + 5.25KB RAM") -> 357.3K gates + 5.25KB RAM
C40: HDR | D40: Support | E40: =IF(D40="Not Support","",IF($D$3=2,"567.7K gates","361.9K gates")) -> 567.7K gates
C41: Scaler | D41: Not Support | E41: =IF(D41="Not Support","",IF($D$3=2,"348.1K gates + 120KB RAM","207.9K gates + 96.56KB RAM"))
...

Sheet ProductFeatureList
A1: Category | C1: DC9X00/DC9X00L Series Product Features | E1: VSI Comment
A2: IP Version | D2: =IF(D7=1,"DC9000","DC9"&D7&"00")&IF(Configuration!D3=1,"L","") -> DC9400
A3: Display Throughput (Resolution@Frame Rate) | C3: Max Display Resolution for Single Display | D3: =IF(Configuration!D3=1,"4K@60fps","4K@120fps") -> 4K@120fps
C4: Max Display Resolution for Multiple Display | D4: =IF(Configuration!D3=1,IF(D7>1,"4K@120fps","Not Support"),IF(D7=1,"Not Support","8K@60fps")) -> 8K@60fps | E4: Multi-Display splice mode
A5: Pixel Thoughput | C5: Pixel Rate (Pixels per Cycle) | D5: =Configuration!D3 -> 2
A6: HW Resource | C6: Pixel Pre-processing | D6: =2 -> 2
C7: Pixel Post-processing | D7: =Configuration!D8 -> 4
A8: Decompression | C8: Input frame buffer decompression | D8: =Configuration!D9 -> DEC400
A9: Data BUS | C9: AXI4.0 address width | D9: 48bit | E9: For Pixel Pre-processing
C10: AXI4.0 read interface | D10: ="4 x"&Configuration!D10 -> 4 x256bits
C11: AXI4.0 write interface | D11: =IF(Configuration!D87="Not Used","Not Support","1x"&Configuration!D10) -> 1x256bits | E11: For Write Back
A12: Config BUS | C12: APB3.0 interface | D12: =D6+1&"x32bits" -> 3x32bits
A13: Pixel Pre-processing | B13: Cursor Layer | D13: =Configuration!D7 -> 4
B14: Layer0 | C14: Layer type | D14: =Configuration!D14 -> Video
C15: Format | D15: =IF(Configuration!D14="Not Used","",IF(Configuration!D14="Video","YUV+RGB format;",IF(Configuration!D14="Graphic","RGB format only;",IF(Configuration!D14="Simple","Linear YUV+RGB format;","ARGB8")))) -> YUV+RGB format;
C16: Tilemode | D16: =IF(Configuration!D14="Not Used","",IF(OR(Configuration!D14="Simple",Configuration!D14="Cursor"),"Linear","Tile&Linear")) -> Tile&Linear
C17: Decompression | D17: =Configuration!D15 -> Support
C18: Max resolution | D18: =IF(Configuration!D14="Not Used","",IF(Configuration!D14="Cursor","256x256","4096x2160")) -> 4096x2160
C19: Rotation with tile input formats | D19: =IF(Configuration!D14="Not Used","",IF(OR(Configuration!D14="Video",Configuration!D14="Graphic"),"Support","Not Support")) -> Support | E19: Rotation 90°/180°/270°
C20: Flip | D20: =IF(Configuration!D14="Not Used","",IF(Configuration!D14="Cursor","Not Support","Support")) -> Support | E20: Flip Y/Flip X/ Flip X&Flip Y
C21: Color Key | D21: =IF(Configuration!D14="Not Used","","Support") -> Support
C22: Crop | D22: =IF(Configuration!D14="Not Used","","Support") -> Support
C23: Swizzle | D23: =IF(Configuration!D14="Not Used","","Support") -> Support
C24: Scaler | D24: =Configuration!D17 -> Support | E24: =IF(Configuration!D17="Support",IF(Configuration!D14="Video",Configuration!G4,""),"") -> Layer number configrable; Default 1; YUV+RGB format; Tile/Rotation/FlipX,Y/Scaler; Fetch up to 4 images from memory by one layer without overlap in vertical (SuperDMA1.0)
C25: HDR | D25: =Configuration!D16 -> Support
C26: YUV2RGB | D26: =IF(Configuration!D14="Not Used","",IF(OR(Configuration!D14="Video",Configuration!D14="Simple"),"Support","Not Support")) -> Support
C27: Solid color | D27: =IF(Configuration!D14="Not Used","","Support") -> Support
B28: Layer1 | C28: Layer type | D28: =Configuration!D18 -> Video
C29: Format | D29: =IF(Configuration!D18="Not Used","",IF(Configuration!D18="Video","YUV+RGB format;",IF(Configuration!D18="Graphic","RGB format only;",IF(Configuration!D18="Simple","Linear YUV+RGB format;","ARGB8")))) -> YUV+RGB format;
C30: Tilemode | D30: =IF(Configuration!D18="Not Used","",IF(OR(Configuration!D18="Simple",Configuration!D18="Cursor"),"Linear","Tile&Linear")) -> Tile&Linear
C31: Decompression | D31: =Configuration!D19 -> Support
C32: Max resolution | D32: =IF(Configuration!D18="Not Used","",IF(Configuration!D18="Cursor","256x256","4096x2160")) -> 4096x2160
C33: Rotation with tile input formats | D33: =IF(Configuration!D18="Not Used","",IF(OR(Configuration!D18="Video",Configuration!D18="Graphic"),"Support","Not Support")) -> Support | E33: Rotation 90°/180°/270°
C34: Flip | D34: =IF(Configuration!D18="Not Used","",IF(Configuration!D18="Cursor","Not Support","Support")) -> Support | E34: Flip Y/Flip X/ Flip X&Flip Y
C35: Color Key | D35: =IF(Configuration!D18="Not Used","","Support") -> Support
C36: Crop | D36: =IF(Configuration!D18="Not Used","","Support") -> Support
C37: Swizzle | D37: =IF(Configuration!D18="Not Used","","Support") -> Support
C38: Scaler | D38: =Configuration!D21 -> Support | E38: =IF(Configuration!D21="Support",IF(Configuration!D18="Video",Configuration!G4,""),"") -> Layer number configrable; Default 1; YUV+RGB format; Tile/Rotation/FlipX,Y/Scaler; Fetch up to 4 images from memory by one layer without overlap in vertical (SuperDMA1.0)
C39: HDR | D39: =Configuration!D20 -> Support
C40: YUV2RGB | D40: =IF(Configuration!D18="Not Used","",IF(OR(Configuration!D18="Video",Configuration!D18="Simple"),"Support","Not Support")) -> Support
...

Sheet CR
A2: Feature | B2: Requests Descriptions | C2: Customer Comment | D2: VSI Comment

Sheet QA
C3: 遗留问题 | D3: comments | E3: VSI Comments
C4: video layer 和 graphic layer 的区别？如果是只差YUV到RGB的转换，是否在VPU中post-processing 增加该转换即可？ | E4: Video： YUV+RGB format; Tile/Rotation/FlipX,Y/Scaler; Fetch up to 4 images from memory by one layer without overlap in vertical (SuperDMA1.0) Graphic： 不支持YUV格式，其余feature 与Video layer相同
C5: DPU 文档中最大支持8个layer。某次讨论中说最大支持12个layer，以哪个为准？ | E5: 12个layer
C6: AXI总线接口 256bits 是否够用？ | D6: 4K@60fps：每行像素：4400，每列像素2250（包含消隐），帧率60。HDR，每像素30bits。 4400*2250*60*30 = 17,820,000,000bit/s = 2,227,500,000Byte/s，约2.2GB每秒。 4个graphic读，4个cursor读，1个写。约11-13GB/s | E6: DPU可以有多个AXI read port . 根据应用场景，我们会推荐3-4个layers对接一个AXI Port 单个AXI Port 32B 宽度，4K60下600MHz AXI Clock，100%带宽大致会在19.2G/s 我们推荐大致占用率在~50% 比较合理 单个4096*2160@60带宽占用在2.2G/s （不考虑压缩） 所以以4个graphic +4 cursor +1 wb 建议配置应该是 2 AXI port ，Port 1：1read+1write , Port 2 1read
C7: DEC400 的配合流程，面积代价？ | E7: By frame enable DEC400 ，上游IP支持，DPU做解压 面积代价配置（不带旋转）343K gate count ；5.25 KB ram
C8: AXI写回能否反压？ | E8: 可以反压
